---
layout: post
title: "Catching errors with Promises"
date: 2015-08-25
---
{% highlight javascript %}
wrapSomethingThrowable() {
  return Promise.resolve()
  .then(() => {
    thisFunctionMayThrowException()
  })
  .catch(ex => {
    // do something with the exception
  })
}
{% endhighlight %}

### Must read
* [We have a problem with promises](https://pouchdb.com/2015/05/18/we-have-a-problem-with-promises.html)